[2025-04-14T21:29:16.674+0000] {local_task_job_runner.py:120} INFO - ::group::Pre task execution logs
[2025-04-14T21:29:16.713+0000] {taskinstance.py:2076} INFO - Dependencies all met for dep_context=non-requeueable deps ti=<TaskInstance: iot_data_pipeline.run_iot_producer_script manual__2025-04-14T21:29:15.441303+00:00 [queued]>
[2025-04-14T21:29:16.723+0000] {taskinstance.py:2076} INFO - Dependencies all met for dep_context=requeueable deps ti=<TaskInstance: iot_data_pipeline.run_iot_producer_script manual__2025-04-14T21:29:15.441303+00:00 [queued]>
[2025-04-14T21:29:16.723+0000] {taskinstance.py:2306} INFO - Starting attempt 1 of 2
[2025-04-14T21:29:16.740+0000] {taskinstance.py:2330} INFO - Executing <Task(BashOperator): run_iot_producer_script> on 2025-04-14 21:29:15.441303+00:00
[2025-04-14T21:29:16.746+0000] {standard_task_runner.py:63} INFO - Started process 757 to run task
[2025-04-14T21:29:16.750+0000] {standard_task_runner.py:90} INFO - Running: ['***', 'tasks', 'run', 'iot_data_pipeline', 'run_iot_producer_script', 'manual__2025-04-14T21:29:15.441303+00:00', '--job-id', '65', '--raw', '--subdir', 'DAGS_FOLDER/iot_data_dag.py', '--cfg-path', '/tmp/tmp5yvln6t0']
[2025-04-14T21:29:16.753+0000] {standard_task_runner.py:91} INFO - Job 65: Subtask run_iot_producer_script
[2025-04-14T21:29:16.804+0000] {task_command.py:426} INFO - Running <TaskInstance: iot_data_pipeline.run_iot_producer_script manual__2025-04-14T21:29:15.441303+00:00 [running]> on host aef507eba48f
[2025-04-14T21:29:16.927+0000] {taskinstance.py:2648} INFO - Exporting env vars: AIRFLOW_CTX_DAG_OWNER='***' AIRFLOW_CTX_DAG_ID='iot_data_pipeline' AIRFLOW_CTX_TASK_ID='run_iot_producer_script' AIRFLOW_CTX_EXECUTION_DATE='2025-04-14T21:29:15.441303+00:00' AIRFLOW_CTX_TRY_NUMBER='1' AIRFLOW_CTX_DAG_RUN_ID='manual__2025-04-14T21:29:15.441303+00:00'
[2025-04-14T21:29:16.927+0000] {taskinstance.py:430} INFO - ::endgroup::
[2025-04-14T21:29:16.942+0000] {subprocess.py:63} INFO - Tmp dir root location: /tmp
[2025-04-14T21:29:16.942+0000] {subprocess.py:75} INFO - Running command: ['/usr/bin/bash', '-c', 'python3 /opt/***/dags/script/iot_data_producer.py']
[2025-04-14T21:29:16.954+0000] {subprocess.py:86} INFO - Output:
[2025-04-14T21:29:17.958+0000] {subprocess.py:93} INFO - Traceback (most recent call last):
[2025-04-14T21:29:17.958+0000] {subprocess.py:93} INFO -   File "/opt/***/dags/script/iot_data_producer.py", line 141, in <module>
[2025-04-14T21:29:17.958+0000] {subprocess.py:93} INFO -     insert_into_postgres(data)
[2025-04-14T21:29:17.959+0000] {subprocess.py:93} INFO -   File "/opt/***/dags/script/iot_data_producer.py", line 116, in insert_into_postgres
[2025-04-14T21:29:17.959+0000] {subprocess.py:93} INFO -     cursor.execute("""
[2025-04-14T21:29:17.959+0000] {subprocess.py:93} INFO - psycopg2.errors.UndefinedColumn: column "latitude" of relation "iot_raw_data" does not exist
[2025-04-14T21:29:17.959+0000] {subprocess.py:93} INFO - LINE 5:             vibration, pressure, latitude, longitude
[2025-04-14T21:29:17.959+0000] {subprocess.py:93} INFO -                                          ^
[2025-04-14T21:29:17.959+0000] {subprocess.py:93} INFO - 
[2025-04-14T21:29:18.049+0000] {subprocess.py:97} INFO - Command exited with return code 1
[2025-04-14T21:29:18.050+0000] {taskinstance.py:441} INFO - ::group::Post task execution logs
[2025-04-14T21:29:18.068+0000] {taskinstance.py:2905} ERROR - Task failed with exception
Traceback (most recent call last):
  File "/home/airflow/.local/lib/python3.10/site-packages/airflow/models/taskinstance.py", line 465, in _execute_task
    result = _execute_callable(context=context, **execute_callable_kwargs)
  File "/home/airflow/.local/lib/python3.10/site-packages/airflow/models/taskinstance.py", line 432, in _execute_callable
    return execute_callable(context=context, **execute_callable_kwargs)
  File "/home/airflow/.local/lib/python3.10/site-packages/airflow/models/baseoperator.py", line 401, in wrapper
    return func(self, *args, **kwargs)
  File "/home/airflow/.local/lib/python3.10/site-packages/airflow/operators/bash.py", line 243, in execute
    raise AirflowException(
airflow.exceptions.AirflowException: Bash command failed. The command returned a non-zero exit code 1.
[2025-04-14T21:29:18.072+0000] {taskinstance.py:1206} INFO - Marking task as UP_FOR_RETRY. dag_id=iot_data_pipeline, task_id=run_iot_producer_script, run_id=manual__2025-04-14T21:29:15.441303+00:00, execution_date=20250414T212915, start_date=20250414T212916, end_date=20250414T212918
[2025-04-14T21:29:18.088+0000] {standard_task_runner.py:110} ERROR - Failed to execute job 65 for task run_iot_producer_script (Bash command failed. The command returned a non-zero exit code 1.; 757)
[2025-04-14T21:29:18.125+0000] {local_task_job_runner.py:240} INFO - Task exited with return code 1
[2025-04-14T21:29:18.144+0000] {taskinstance.py:3503} INFO - 0 downstream tasks scheduled from follow-on schedule check
[2025-04-14T21:29:18.145+0000] {local_task_job_runner.py:222} INFO - ::endgroup::
